Workbook

Sheet 📊 Dashboard
A1: INFOBIP | MID-TIER GROWTH ACCOUNTS — RETAIL 2025 | GESTÃO OPERACIONAL 2025
A2: Bloco de foco: 20 contas prioritárias para crescimento ao longo de 2025
A4: Contas no Foco
A5: =COUNTA('📋 Carteira'!A3:A22) -> 20
A9: SEGMENTAÇÃO POR CATEGORIA DE AÇÃO
A10: Categoria | C10: Qtd Contas | D10: Receita Total | E10: GP Total | F10: Margem Média | G10: Ação Prioritária | H10: Prazo
A11: 🚀 Acelerar | C11: 2 | D11: $15,680 | E11: $18,753 | F11: 97.5% | G11: Expandir canais e volume | H11: Imediato
A12: 📈 Manter Momentum | C12: 3 | D12: $53,580 | E12: $34,290 | F12: 64.0% | G12: QBR + oferta de expansão proativa | H12: 30 dias
A13: 🎯 Recuperação Fácil | C13: 7 | D13: $65,809 | E13: $60,539 | F13: 84.2% | G13: Call proativo + revisão de uso | H13: 30 dias
A14: ⚠️ Recuperar | C14: 3 | D14: $39,056 | E14: $29,897 | F14: 76.5% | G14: Diagnóstico de causa + plano de ação | H14: 45 dias
A15: 🚨 Intervenção Urgente | C15: 1 | D15: $20,526 | E15: $19,047 | F15: 92.8% | G15: Escalada comercial imediata | H15: 7 dias
A16: 🔍 Novos — Ativar | C16: 2 | D16: $11,583 | E16: $5,511 | F16: 47.6% | G16: Onboarding + mapeamento de uso | H16: 60 dias
A18: TOP 5 CONTAS — MAIOR RECEITA NO BLOCO
A19: # | C19: Conta | D19: Receita (USD) | E19: GP (USD) | F19: Margem | G19: Tendência | H19: Status
A20: 1 | C20: Wiser | D20: 26062 | E20: 15637 | F20: 0.6 | G20: -0.365 | H20: ⚠️ Recuperar
A21: 2 | C21: Azul Linhas Aereas | D21: 23739 | E21: 18719 | F21: 0.79 | G21: 0.027 | H21: 📈 Manter Momentum
A22: 3 | C22: Hospital Oswaldo Cruz | D22: 20714 | E22: 17228 | F22: 0.83 | G22: -0.193 | H22: 🎯 Recuperar
A23: 4 | C23: McDonalds Brazil | D23: 20526 | E23: 19047 | F23: 0.93 | G23: -0.795 | H23: 🚨 Urgente
A24: 5 | C24: Outback Brazil | D24: 15619 | E24: 5098 | F24: 0.33 | G24: 0.313 | H24: 📈 Manter Momentum
A26: 5 INSIGHTS CRÍTICOS DO BLOCO
A27: #
A28: 1
A29: 2
A30: 3
A31: 4
A32: 5
A34: VISÃO GERAL DA CARTEIRA — COMPARATIVO POR TIER (fonte: Base de Dados)
A35: Tier | C35: Contas | D35: Receita (USD) | E35: GP (USD) | F35: Margem
A36: 🔝 Topo | C36: 30 | D36: 2285949 | E36: 1092693 | F36: 0.478
A37: 🎯 Mid-Tier (Foco) | C37: 20 | D37: 238405 | E37: 178508 | F37: 0.748
A38: 📉 Base | C38: 31 | D38: 201 | E38: 149 | F38: 0.741
A40: 📌 NAVEGAÇÃO RÁPIDA: 📋 Carteira → operacional conta a conta | 🎯 Plano de Ação → iniciativas priorizadas | 📈 Gráficos → visualizações | 📅 Tracker → metas mensais | 🗄️ Base de Dados → extração completa

Sheet 📋 Carteira
A1: MID-TIER GROWTH ACCOUNTS — RETAIL 2025 | 20 CONTAS PRIORITÁRIAS 2025
A2: # | B2: Conta | C2: Receita (USD) | D2: GP (USD) | E2: Margem % | F2: Trend Receita vs LQTD | G2: Status Baseline | H2: Variação GP vs LQTD | I2: Categoria de Ação | J2: Ação Recomendada | K2: Prazo | L2: CSM Responsável | M2: Próximo Contato | N2: Meta Receita Q2 (USD) | O2: Meta GP Q2 (USD) | P2: Prioridade | Q2: Setor | R2: Observações
A3: 1 | B3: Wiser | C3: 26062 | D3: 15637 | E3: 0.5993 | F3: -0.3651 | G3: Em queda | H3: -0.1716 | I3: ⚠️ Recuperar | J3: Diagnóstico de causa + reunião de alinhamento de uso | K3: 45 dias | L3: A definir | M3: A agendar | N3: =26062*1.3 -> 33880.6 | O3: =15637*1.3 -> 20328.1 | P3: P2 — Alto | Q3: Tecnologia / SaaS | R3: Maior receita do bloco. Queda relevante — investigar mudança de interlocutor ou competitor.
A4: 2 | B4: Azul Linhas Aereas | C4: 23739 | D4: 18719 | E4: 0.7887 | F4: 0.0265 | G4: Crescendo | H4: -0.142 | I4: 📈 Manter Momentum | J4: QBR trimestral + proposta de expansão de canal | K4: 30 dias | L4: A definir | M4: A agendar | N4: =23739*1.2 -> 28486.8 | O4: =18719*1.2 -> 22462.8 | P4: P2 — Alto | Q4: Aviação | R4: GP caindo mesmo com receita crescendo — revisar estrutura de custo do produto em uso.
A5: 3 | B5: Hospital Oswaldo Cruz | C5: 20714 | D5: 17228 | E5: 0.8322 | F5: -0.1928 | G5: Em queda | H5: -0.0282 | I5: 🎯 Recuperação Fácil | J5: Call proativo + revisão de campanhas ativas | K5: 30 dias | L5: A definir | M5: A agendar | N5: =20714*1.3 -> 26928.2 | O5: =17228*1.3 -> 22396.4 | P5: P3 — Médio | Q5: Saúde | R5: Queda leve. Alta margem. Alta probabilidade de recuperação com ação simples.
A6: 4 | B6: McDonalds Brazil | C6: 20526 | D6: 19047 | E6: 0.9272 | F6: -0.7945 | G6: Em queda | H6: -0.7741 | I6: 🚨 Intervenção Urgente | J6: Escalada comercial imediata — reunião C-level em até 7 dias | K6: 7 dias | L6: A definir | M6: A agendar | N6: =20526*1.3 -> 26683.8 | O6: =19047*1.3 -> 24761.1 | P6: P1 — Crítico | Q6: Food & Beverage | R6: ALERTA: queda de 79.5% com maior margem do bloco (93%). Investigar perda de campanha.
A7: 5 | B7: Outback Brazil | C7: 15619 | D7: 5098 | E7: 0.3257 | F7: 0.3134 | G7: Crescendo | H7: -0.0303 | I7: 📈 Manter Momentum | J7: Ampliar volume de envios e mapear novos casos de uso | K7: 30 dias | L7: A definir | M7: A agendar | N7: =15619*1.2 -> 18742.8 | O7: =5098*1.2 -> 6117.6 | P7: P2 — Alto | Q7: Food & Beverage | R7: Crescimento positivo mas GP caindo — verificar mix de canais utilizados.
A8: 6 | B8: Pernod Ricard | C8: 15608 | D8: 14092 | E8: 0.9019 | F8: -0.0039 | G8: Em queda | H8: 0.1734 | I8: 🎯 Recuperação Fácil | J8: Proposta de expansão — GP crescendo mesmo com receita flat | K8: 30 dias | L8: A definir | M8: A agendar | N8: =15608*1.3 -> 20290.4 | O8: =14092*1.3 -> 18319.6 | P8: P3 — Médio | Q8: Bebidas / FMCG | R8: GP subindo mesmo com receita quase flat. Bom sinal — conta melhorando qualidade.
A9: 7 | B9: MaxMilhas | C9: 14222 | D9: 5573 | E9: 0.3922 | F9: 0.3049 | G9: Crescendo | H9: 0.1953 | I9: 📈 Manter Momentum | J9: Ampliar volume + explorar novos canais (WhatsApp / Push) | K9: 30 dias | L9: A definir | M9: A agendar | N9: =14222*1.2 -> 17066.4 | O9: =5573*1.2 -> 6687.6 | P9: P2 — Alto | Q9: Viagens / Fidelidade | R9: Crescimento consistente. Margem baixa — upsell para canais de maior margem.
A10: 8 | B10: Positivo Tecnologia | C10: 13995 | D10: 13664 | E10: 0.9764 | F10: -0.019 | G10: Em queda | H10: -0.0205 | I10: 🎯 Recuperação Fácil | J10: Revisão de cases ativos + proposta de expansão de volume | K10: 30 dias | L10: A definir | M10: A agendar | N10: =13995*1.3 -> 18193.5 | O10: =13664*1.3 -> 17763.2 | P10: P3 — Médio | Q10: Tecnologia | R10: 98% de margem com queda mínima (-1.9%). Potencial de recuperação fácil e rápida.
A11: 9 | B11: Ecohouse | C11: 12407 | D11: 10893 | E11: 0.8777 | F11: 0.2633 | G11: Crescendo | H11: 0.3883 | I11: 🚀 Acelerar | J11: Replicar playbook + expandir canais adicionais agora | K11: Imediato | L11: A definir | M11: A agendar | N11: =12407*1.2 -> 14888.4 | O11: =10893*1.2 -> 13071.6 | P11: P1 — Crítico | Q11: Energia / ESG | R11: Crescimento forte em receita e GP. Conta modelo — extrair insights para replicar.
A12: 10 | B12: Burger King Brasil | C12: 11808 | D12: 6025 | E12: 0.5102 | F12: -0.0257 | G12: Em queda | H12: -0.1222 | I12: 🎯 Recuperação Fácil | J12: Revisão de campanhas + proposta de automação de comunicação | K12: 30 dias | L12: A definir | M12: A agendar | N12: =11808*1.3 -> 15350.4 | O12: =6025*1.3 -> 7832.5 | P12: P3 — Médio | Q12: Food & Beverage | R12: Queda mínima (-2.6%). Setor F&B com alto potencial de uso de WhatsApp e SMS.
A13: 11 | B13: Cia Hering | C13: 11583 | D13: 5511 | E13: 0.476 | F13: N/D | G13: Novo / Sem dado | H13: N/D | I13: 🔍 Ativar — Novo Cliente | J13: Onboarding estruturado + definição de KPIs de sucesso | K13: 60 dias | L13: A definir | M13: A agendar | N13: =11583*1.25 -> 14478.75 | O13: =5511*1.25 -> 6888.75 | P13: P3 — Médio | Q13: Varejo / Moda | R13: Cliente novo entrante. Sem baseline comparativo. Foco em ativação e primeiro caso de uso.
A14: 12 | B14: Edenred Brazil - Freto | C14: 9314 | D14: 8647 | E14: 0.9283 | F14: -0.0191 | G14: Em queda | H14: -0.0114 | I14: 🎯 Recuperação Fácil | J14: Call proativo — queda mínima, alta margem | K14: 30 dias | L14: A definir | M14: A agendar | N14: =9314*1.3 -> 12108.2 | O14: =8647*1.3 -> 11241.1 | P14: P3 — Médio | Q14: RH / Benefícios | R14: Margem de 93% com queda irrelevante (-1.9%). Fácil de recuperar com contato proativo.
A15: 13 | B15: Boticario Brazil | C15: 7840 | D15: 7840 | E15: 1 | F15: 1.7927 | G15: Crescendo | H15: 1.7927 | I15: 🚀 Acelerar | J15: Aprofundar integração + proposta de novos canais imediatamente | K15: Imediato | L15: A definir | M15: A agendar | N15: =7840*1.2 -> 9408 | O15: =7840*1.2 -> 9408 | P15: P1 — Crítico | Q15: Beleza / Cosméticos | R15: CONTA MODELO: +179% receita com 100% margem. Entender driver e replicar no bloco.
A16: 14 | B16: Atlas Schindler | C16: 7397 | D16: 6663 | E16: 0.9008 | F16: -0.3928 | G16: Em queda | H16: -0.4458 | I16: ⚠️ Recuperar | J16: Reunião para diagnóstico — queda acentuada em conta de alta margem | K16: 45 dias | L16: A definir | M16: A agendar | N16: =7397*1.3 -> 9616.1 | O16: =6663*1.3 -> 8661.9 | P16: P2 — Alto | Q16: Elevadores / B2B | R16: 90% de margem caindo -39%. Pode ser mudança de interlocutor ou redução de operação.
A17: 15 | B17: Sumicity | C17: 6916 | D17: 4997 | E17: 0.7223 | F17: -0.1946 | G17: Em queda | H17: -0.2862 | I17: 🎯 Recuperação Fácil | J17: Revisão de uso + proposta de expansão de casos de uso | K17: 30 dias | L17: A definir | M17: A agendar | N17: =6916*1.3 -> 8990.8 | O17: =4997*1.3 -> 6496.1 | P17: P3 — Médio | Q17: Telecom | R17: ISP regional. Queda moderada. Setor com alto volume natural — explorar mais canais.
A18: 16 | B18: Rede dor | C18: 6742 | D18: 6742 | E18: 1 | F18: -0.0097 | G18: Em queda | H18: -0.0132 | I18: 🎯 Recuperação Fácil | J18: Contato proativo — queda insignificante, 100% margem | K18: 30 dias | L18: A definir | M18: A agendar | N18: =6742*1.3 -> 8764.6 | O18: =6742*1.3 -> 8764.6 | P18: P3 — Médio | Q18: Saúde | R18: 100% de margem com queda de apenas 1%. Conta praticamente estável. Fácil de manter.
A19: 17 | B19: IBM Brasil | C19: 5597 | D19: 5597 | E19: 1 | F19: -0.3354 | G19: Em queda | H19: -0.3354 | I19: ⚠️ Recuperar | J19: Diagnóstico urgente — conta 100% margem caindo -33% | K19: 45 dias | L19: A definir | M19: A agendar | N19: =5597*1.3 -> 7276.1 | O19: =5597*1.3 -> 7276.1 | P19: P2 — Alto | Q19: Tecnologia / B2B | R19: 100% margem caindo -33%. Alta probabilidade de redução de projeto ou mudança de interlocutor.
A20: 18 | B20: GOL LINHAS AEREAS | C20: 4632 | D20: 2859 | E20: 0.6169 | F20: -0.1311 | G20: Em queda | H20: -0.1636 | I20: 🎯 Recuperação Fácil | J20: Call proativo + proposta de uso para campanhas sazonais | K20: 30 dias | L20: A definir | M20: A agendar | N20: =4632*1.3 -> 6021.6 | O20: =2859*1.3 -> 3716.7 | P20: P3 — Médio | Q20: Aviação | R20: Queda moderada (-13%). Aviação tem sazonalidade — verificar se é estrutural ou sazonal.
A21: 19 | B21: LARCO BRAZIL | C21: 3686 | D21: 3676 | E21: 0.9974 | F21: -0.1779 | G21: Em queda | H21: -0.1736 | I21: 🎯 Recuperação Fácil | J21: Revisão de campanhas ativas + expansão de volume | K21: 30 dias | L21: A definir | M21: A agendar | N21: =3686*1.3 -> 4791.8 | O21: =3676*1.3 -> 4778.8 | P21: P3 — Médio | Q21: Distribuição / B2B | R21: 100% margem com queda de -17.8%. Conta pequena mas rentável — fácil de recuperar.
A22: 20 | B22: Grupo Mateus | C22: 0 | D22: 0 | F22: N/D | G22: Novo / Sem dado | H22: N/D | I22: 🔍 Ativar — Novo Cliente | J22: Onboarding + mapeamento de casos de uso — cadastrar no CRM | K22: 60 dias | L22: A definir | M22: A agendar | N22: A definir | O22: A definir | P22: P3 — Médio | Q22: Varejo / Supermercados | R22: NOVO: não consta na extração atual. Validar cadastro no CRM/billing imediatamente.
A23: TOTAIS DO BLOCO | C23: =SUM(C3:C22) -> 238407 | D23: =SUM(D3:D22) -> 178508 | E23: =IFERROR(D23/C23,"") -> 0.74875318

Sheet 🎯 Plano de Ação
A1: PLANO DE AÇÃO PRIORIZADO | MID-TIER GROWTH ACCOUNTS — RETAIL 2025
A3: MATRIZ DE PRIORIDADES — IMPACTO × ESFORÇO
A4: Prioridade | B4: Conta(s) | C4: Ação Específica | D4: Impacto Esperado | E4: Esforço | F4: Prazo | G4: KPI de Sucesso | H4: Responsável | I4: Status | J4: Notas / Dependências | K4: Impacto $ | L4: % do Bloco
A5: P1 — 🚨 CRÍTICO | B5: McDonalds Brazil | C5: Escalada comercial C-level em até 7 dias. Identificar motivo da queda de -79.5% e apresentar proposta de reativação com incentivo. | D5: Recuperar 50% do volume perdido = +$9.7k GP de 93% de margem | E5: Alto | F5: 7 dias | G5: Receita ≥ $12k no próximo mês | H5: Gerente de Vendas Sênior | I5: 🔴 Pendente | J5: Escalar para CRO se não houver resposta em 48h. Verificar se há contrato vigente. | K5: 9700 | L5: 0.054
A6: P1 — 🚨 CRÍTICO | B6: Boticário Brazil + Ecohouse | C6: Extrair e documentar drivers de crescimento dessas 2 contas. Replicar playbook para Cia Hering, Outback e MaxMilhas. | D6: Se 3 contas replicarem 50% do crescimento do Boticário = +$12k receita | E6: Médio | F6: Imediato | G6: 3 contas com crescimento positivo no próximo Q | H6: CSM + AM | I6: 🔴 Pendente | J6: Documentar: qual canal, qual caso de uso, qual frequência. Criar template replicável. | K6: 12000 | L6: 0.05
A7: P1 — ⚠️ CRÍTICO | B7: Wiser + IBM + Atlas Schindler | C7: Reunião de diagnóstico em até 2 semanas. Identificar causa raiz da queda. Apresentar plano de recuperação específico por conta. | D7: Recuperar 30% do volume = +$11.6k em receita combinada | E7: Alto | F7: 45 dias | G7: Queda estabilizada; crescimento no mês seguinte | H7: AM + CSM | I7: 🔴 Pendente | J7: Risco de churn parcial. Mapear se há mudança de interlocutor ou de produto. | K7: 11600 | L7: 0.049
A8: P2 — 📈 ALTO | B8: Azul Linhas Aereas + MaxMilhas + Outback | C8: QBR estruturado + proposta de expansão de canais (WhatsApp / Email / Push). Garantir que momentum não seja perdido por falta de atenção. | D8: Crescimento adicional de 15-20% nas 3 contas = +$8k receita | E8: Médio | F8: 30 dias | G8: Crescimento MoM positivo por 2 meses consecutivos | H8: CSM | I8: 🟡 Em andamento | J8: Azul: revisar estrutura de custo — GP caindo mesmo com receita subindo. | K8: 8000 | L8: 0.034
A9: P2 — 🎯 ALTO | B9: Hospital Oswaldo Cruz + Pernod + Positivo + Edenred + Rede Dor + GOL + LARCO + Sumicity + Burger King | C9: Call proativo para todas as 9 contas de recuperação fácil. Script padrão: revisão de uso + nova proposta. Meta: 1 reunião por conta em 30 dias. | D9: Recuperar 30% das 9 contas = +$13.5k receita incremental | E9: Médio | F9: 30 dias | G9: ≥ 6 das 9 contas com receita positiva vs mês atual | H9: CSM | I9: 🟡 Pendente | J9: Criar campanha interna de contato proativo. Estas contas têm alta margem e baixa necessidade de esforço. | K9: 13500 | L9: 0.057
A10: P3 — 🔍 MÉDIO | B10: Cia Hering + Grupo Mateus | C10: Estruturar onboarding: (1) definir caso de uso inicial, (2) configurar integração, (3) meta de receita para 60/90/120 dias, (4) QBR de 30 dias. | D10: Ativar 2 contas novas com receita >$5k cada em até 90 dias | E10: Baixo | F10: 60 dias | G10: Primeira receita registrada em até 45 dias | H10: CSM Onboarding | I10: 🟡 Pendente | J10: URGENTE: Grupo Mateus não está no sistema. Confirmar cadastro no CRM/billing antes de qualquer ação comercial. | K10: 10000 | L10: 0.042
A11: P3 — 📊 ESTRATÉGICO | B11: Bloco completo (20 contas) | C11: Criar cadência de revisão mensal do bloco: scorecard de saúde por conta, atualização de metas, alerta automático para contas com queda >15% MoM. | D11: Prevenção de churn e aumento de visibilidade sobre o bloco | E11: Baixo | F11: 30 dias | G11: Scorecard atualizado mensalmente; 0 contas com churn no Q | H11: Gerente de Vendas | I11: 🟡 Pendente | J11: Usar esta planilha como base. Sugerir atualização mensal com dados do sistema. | L11: 0

Sheet 📈 Gráficos
A1: ANÁLISE VISUAL | MID-TIER GROWTH ACCOUNTS — RETAIL 2025 | 20 CONTAS PRIORITÁRIAS
A3: Dados — Receita por Conta | E3: Dados — Margem | H3: Dados — Tendência Receita | K3: Dados — Categorias
A4: Conta | B4: Receita (USD) | C4: Gross Profit (USD) | E4: Conta | F4: Margem % | H4: Conta | I4: Trend vs LQTD | K4: Categoria | L4: Qtd | M4: Receita
A5: Wiser | B5: 26062 | C5: 15637 | E5: Wiser | F5: 0.5993 | H5: Boticario Brazil | I5: 1.7927 | K5: 🚀 Acelerar | L5: 2 | M5: 20247
A6: Azul Linhas Aereas | B6: 23739 | C6: 18719 | E6: Azul Linhas Aereas | F6: 0.7887 | H6: Ecohouse | I6: 0.2633 | K6: 📈 Manter Momentum | L6: 3 | M6: 53580
A7: Hospital Oswaldo Cruz | B7: 20714 | C7: 17228 | E7: Hospital Oswaldo Cruz | F7: 0.8322 | H7: MaxMilhas | I7: 0.3049 | K7: 🎯 Recuperação Fácil | L7: 7 | M7: 65809
A8: McDonalds Brazil | B8: 20526 | C8: 19047 | E8: McDonalds Brazil | F8: 0.9272 | H8: Outback Brazil | I8: 0.3134 | K8: ⚠️ Recuperar | L8: 3 | M8: 39056
A9: Outback Brazil | B9: 15619 | C9: 5098 | E9: Outback Brazil | F9: 0.3257 | H9: Azul Linhas Aereas | I9: 0.0265 | K9: 🚨 Urgente | L9: 1 | M9: 20526
A10: Pernod Ricard | B10: 15608 | C10: 14092 | E10: Pernod Ricard | F10: 0.9019 | H10: Pernod Ricard | I10: -0.0039 | K10: 🔍 Novos — Ativar | L10: 2 | M10: 11583
A11: MaxMilhas | B11: 14222 | C11: 5573 | E11: MaxMilhas | F11: 0.3922 | H11: Burger King Brasil | I11: -0.0257
A12: Positivo Tecnologia | B12: 13995 | C12: 13664 | E12: Positivo Tecnologia | F12: 0.9764 | H12: Edenred Brazil - Freto | I12: -0.0191
A13: Ecohouse | B13: 12407 | C13: 10893 | E13: Ecohouse | F13: 0.8777 | H13: Rede dor | I13: -0.0097
A14: Burger King Brasil | B14: 11808 | C14: 6025 | E14: Burger King Brasil | F14: 0.5102 | H14: Positivo Tecnologia | I14: -0.019
A15: Cia Hering | B15: 11583 | C15: 5511 | E15: Cia Hering | F15: 0.476 | H15: GOL LINHAS AEREAS | I15: -0.1311
A16: Edenred Brazil - Freto | B16: 9314 | C16: 8647 | E16: Edenred Brazil - Freto | F16: 0.9283 | H16: LARCO BRAZIL | I16: -0.1779
A17: Boticario Brazil | B17: 7840 | C17: 7840 | E17: Boticario Brazil | F17: 1 | H17: Hospital Oswaldo Cruz | I17: -0.1928
A18: Atlas Schindler | B18: 7397 | C18: 6663 | E18: Atlas Schindler | F18: 0.9008 | H18: Sumicity | I18: -0.1946
A19: Sumicity | B19: 6916 | C19: 4997 | E19: Sumicity | F19: 0.7223 | H19: Wiser | I19: -0.3651
A20: Rede dor | B20: 6742 | C20: 6742 | E20: Rede dor | F20: 1 | H20: IBM Brasil | I20: -0.3354
A21: IBM Brasil | B21: 5597 | C21: 5597 | E21: IBM Brasil | F21: 1 | H21: Atlas Schindler | I21: -0.3928
A22: GOL LINHAS AEREAS | B22: 4632 | C22: 2859 | E22: GOL LINHAS AEREAS | F22: 0.6169 | H22: McDonalds Brazil | I22: -0.7945
A23: LARCO BRAZIL | B23: 3686 | C23: 3676 | E23: LARCO BRAZIL | F23: 0.9974
A24: Grupo Mateus | B24: 0 | C24: 0

Sheet 📅 Tracker Mensal
A1: TRACKER DE ACOMPANHAMENTO MENSAL | 20 CONTAS — 2025
A3: Conta | B3: Meta Anual (USD) | C3: Receita Atual | D3: Mar/25 | E3: Abr/25 | F3: Mai/25 | G3: Jun/25 | H3: Jul/25 | I3: Ago/25 | J3: Set/25 | K3: Out/25 | L3: Nov/25 | M3: Dez/25 | N3: Total Realizado
A4: Wiser | B4: 33880 | C4: ='📋 Carteira'!C3 -> 26062 | D4: ← preencher | N4: =SUM(D4:M4) -> 0
A5: Azul Linhas Aereas | B5: 28487 | C5: ='📋 Carteira'!C4 -> 23739 | D5: ← preencher | N5: =SUM(D5:M5) -> 0
A6: Hospital Oswaldo Cruz | B6: 26928 | C6: ='📋 Carteira'!C5 -> 20714 | D6: ← preencher | N6: =SUM(D6:M6) -> 0
A7: McDonalds Brazil | B7: 26683 | C7: ='📋 Carteira'!C6 -> 20526 | D7: ← preencher | N7: =SUM(D7:M7) -> 0
A8: Outback Brazil | B8: 20305 | C8: ='📋 Carteira'!C7 -> 15619 | D8: ← preencher | N8: =SUM(D8:M8) -> 0
A9: Pernod Ricard | B9: 20290 | C9: ='📋 Carteira'!C8 -> 15608 | D9: ← preencher | N9: =SUM(D9:M9) -> 0
A10: MaxMilhas | B10: 18489 | C10: ='📋 Carteira'!C9 -> 14222 | D10: ← preencher | N10: =SUM(D10:M10) -> 0
A11: Positivo Tecnologia | B11: 18194 | C11: ='📋 Carteira'!C10 -> 13995 | D11: ← preencher | N11: =SUM(D11:M11) -> 0
A12: Ecohouse | B12: 16129 | C12: ='📋 Carteira'!C11 -> 12407 | D12: ← preencher | N12: =SUM(D12:M12) -> 0
A13: Burger King Brasil | B13: 15350 | C13: ='📋 Carteira'!C12 -> 11808 | D13: ← preencher | N13: =SUM(D13:M13) -> 0
A14: Cia Hering | B14: 17375 | C14: ='📋 Carteira'!C13 -> 11583 | D14: ← preencher | N14: =SUM(D14:M14) -> 0
A15: Edenred Brazil - Freto | B15: 12108 | C15: ='📋 Carteira'!C14 -> 9314 | D15: ← preencher | N15: =SUM(D15:M15) -> 0
... A23: Grupo Mateus | B23: 8000 | C23: ='📋 Carteira'!C22 -> 0 | D23: ← preencher | N23: =SUM(D23:M23) -> 0
A24: TOTAL BLOCO | B24: =SUM(B4:B23) -> 317870 | C24: =SUM(C4:C23) -> 238407 | D24: =SUM(D4:D23) -> 0 | E24: =SUM(E4:E23) -> 0 | F24: =SUM(F4:F23) -> 0 | G24: =SUM(G4:G23) -> 0 | H24: =SUM(H4:H23) -> 0 | I24: =SUM(I4:I23) -> 0 | ... N24: =SUM(N4:N23) -> 0
A26: LEGENDA DAS METAS ANUAIS
A27: Contas crescendo (trend >0): | B27: Meta = Receita atual × 1.2 (+20%)
A28: Contas em queda (trend <0): | B28: Meta = Receita atual × 1.3 (recuperação de 30%)
A29: Contas novas (sem baseline): | B29: Meta = Receita atual × 1.25 ou definida pelo AM
A30: Coluna amarela (Mar/25): | B30: Preencher com receita realizada no mês — atualizar mensalmente

Sheet 🗄️ Base de Dados
A1: BASE DE DADOS COMPLETA | RETAIL — CARTEIRA TOTAL | Fonte: Extração Q Atual vs LQTD
A2: Total de contas: 91 | Topo: 30 contas | Mid-Tier (foco): 30 contas | Base: 31 contas | Atualizar mensalmente com nova extração
A3: CARTEIRA TOTAL | E3: TOPO (30 contas) | H3: MID-TIER FOCO (20 contas) | K3: BASE (31 contas)
A4: Receita Total | B4: GP Total | D4: Margem Média | E4: Receita Total | F4: GP Total | G4: Margem Média | H4: Receita Total | I4: GP Total | J4: Margem Média | K4: Receita Total | L4: GP Total | M4: Margem Média
A5: 2433574.6 | B5: 1270996.2 | D5: 0.52227541 | E5: 2058439.7 | F5: 1039464.6 | G5: 0.50497698 | H5: 347673.93 | I5: 216309.59 | J5: 0.62216224 | K5: 27460.966 | L5: 15221.92 | M5: 0.55431116
A7: # | B7: Conta | C7: Account Owner | D7: Tier / Bloco | E7: No Foco 2025 | F7: Interações (Ch. → Client) | G7: Receita (USD) | H7: Gross Profit (USD) | I7: Margem % | J7: Var. Interações vs LQTD | K7: Var. Receita vs LQTD | L7: Var. GP vs LQTD | M7: Receita % do Total | N7: GP % do Total | O7: Ranking (por Receita) | P7: Observação
A8: 1 | B8: VERO Internet - Cagliari | C8: Josue Moro | D8: 🔝 Topo | F8: 33063248 | G8: 187822.89 | H8: 111584.56 | I8: 0.59368723 | J8: -0.32115497 | K8: -0.12835518 | L8: -0.26918325 | M8: 0.077179837 | N8: 0.087792995 | O8: 1 | P8: Conta de alto volume — gestão pelo time de key accounts
A9: 2 | B9: Mercafacil | C9: Cintya Camargo | D9: 🔝 Topo | F9: 28577420 | G9: 143271.7 | H9: 25580.394 | I9: 0.17845337 | J9: 0.47034414 | K9: 1.0026935 | L9: 0.45943695 | M9: 0.058872944 | N9: 0.020126256 | O9: 2 | P9: Conta de alto volume — gestão pelo time de key accounts
A10: 3 | B10: Ambev Ab-Inbev | C10: Cintya Camargo | D10: 🔝 Topo | F10: 1629750 | G10: 142729.21 | H10: 65863.125 | I10: 0.46121319 | J10: 0.040998365 | K10: 0.75788615 | L10: 1.2555759 | M10: 0.058650027 | N10: 0.051820082 | O10: 3 | P10: Conta de alto volume — gestão pelo time de key accounts
A11: 4 | B11: ENEL Eletropaulo | C11: Josue Moro | D11: 🔝 Topo | F11: 32455054 | G11: 118155.37 | H11: 18908.77 | I11: 0.16030008 | J11: -0.38462784 | K11: -0.078450036 | L11: -0.05321975 | M11: 0.048552187 | N11: 0.014877126 | O11: 4 | P11: Conta de alto volume — gestão pelo time de key accounts
A12: 5 | B12: Whirlpool do Brasil | C12: Cintya Camargo | D12: 🔝 Topo | F12: 24218534 | G12: 112521.03 | H12: 62935.567 | I12: 0.55853953 | J12: N/D | K12: -0.11403827 | L12: -0.16441039 | M12: 0.046236937 | N12: 0.049516725 | O12: 5 | P12: Conta de alto volume — gestão pelo time de key accounts
A13: 6 | B13: LIGO SAGO | C13: Julia Nunes | D13: 🔝 Topo | F13: 12336197 | G13: 105062.88 | H13: 32916.458 | I13: 0.31312992 | J13: 0.077097329 | K13: -0.014960996 | L13: -0.023801958 | M13: 0.043172245 | N13: 0.025898157 | O13: 6 | P13: Conta de alto volume — gestão pelo time de key accounts
A14: 7 | B14: Brisanet | C14: Josue Moro | D14: 🔝 Topo | F14: 7985570 | G14: 99075.625 | H14: 46884.045 | I14: 0.47293714 | J14: 0.028078789 | K14: 0.47787609 | L14: 0.59497888 | M14: 0.040711974 | N14: 0.036887638 | O14: 7 | P14: Conta de alto volume — gestão pelo time de key accounts
A15: 8 | B15: Medcof Educacao S.A | C15: Anne Tulio | D15: 🔝 Topo | F15: 2511017 | G15: 99026.37 | H15: 28722.181 | I15: 0.28967865 | J15: 1.1497705 | K15: 1.1913866 | L15: 1.1102523 | M15: 0.040691735 | N15: 0.022598166 | O15: 8 | P15: Conta de alto volume — gestão pelo time de key accounts
A16: 9 | B16: MadeiraMadeira | C16: Anne Tulio | D16: 🔝 Topo | F16: 2457371 | G16: 98488.903 | H16: 45543.82 | I16: 0.46223254 | J16: -0.093370022 | K16: 0.021366015 | L16: 0.0099132402 | M16: 0.04047088 | N16: 0.035833169 | O16: 9 | P16: Conta de alto volume — gestão pelo time de key accounts
A17: 10 | B17: CEMIG | C17: Cintya Camargo | D17: 🔝 Topo | F17: 87949 | G17: 93722.362 | H17: 93225.422 | I17: 0.99467931 | J17: -0.35234976 | K17: -0.0055216488 | L17: -0.0044564006 | M17: 0.038512222 | N17: 0.073348312 | O17: 10 | P17: Conta de alto volume — gestão pelo time de key accounts
A18: 11 | B18: Grupo Alloha | C18: Josue Moro | D18: 🔝 Topo | F18: 495621 | G18: 76613.569 | H18: 49644.757 | I18: 0.64727979 | J18: -0.39223683 | K18: -0.13466679 | L18: -0.051743717 | M18: 0.031481908 | N18: 0.039059723 | O18: 11 | P18: Conta de alto volume — gestão pelo time de key accounts
A19: 12 | B19: Motorola | C19: Anne Tulio | D19: 🔝 Topo | F19: 806368 | G19: 65952.627 | H19: 42978.127 | I19: 0.651033 | J19: 0.77315386 | K19: 2.8904504 | L19: N/D | M19: 0.027101133 | N19: 0.033814521 | O19: 12 | P19: Conta de alto volume — gestão pelo time de key accounts
A20: 13 | B20: Danone Brasil | C20: Cintya Camargo | D20: 🔝 Topo | F20: 342780 | G20: 54819.874 | H20: 50841.676 | I20: 0.92687991 | J20: 0.2823354 | K20: 1.4432436 | L20: 1.4484318 | M20: 0.022526482 | N20: 0.04000144 | O20: 13 | P20: Conta de alto volume — gestão pelo time de key accounts
A21: 14 | B21: Webmotors | C21: Julia Nunes | D21: 🔝 Topo | F21: 219170 | G21: 51274.55 | H21: 43113.507 | I21: 0.84061102 | J21: -0.071975585 | K21: -0.1257211 | L21: -0.12785157 | M21: 0.021069644 | N21: 0.033921037 | O21: 14 | P21: Conta de alto volume — gestão pelo time de key accounts
A22: 15 | B22: PUC RS | C22: Julia Nunes | D22: 🔝 Topo | F22: 838753 | G22: 50736.5 | H22: 31681.298 | I22: 0.6236561 | J22: 0.086360047 | K22: 0.064971057 | L22: -0.040317256 | M22: 0.02084855 | N22: 0.024926352 | O22: 15 | P22: Conta de alto volume — gestão pelo time de key accounts
A23: 16 | B23: Samsung Electronics Brazil | C23: Anne Tulio | D23: 🔝 Topo | F23: 622477 | G23: 48178.234 | H23: 29968.002 | I23: 0.62155551 | J23: -0.34299027 | K23: -0.26358543 | L23: -0.33068666 | M23: 0.019797312 | N23: 0.023578358 | O23: 16 | P23: Conta de alto volume — gestão pelo time de key accounts
A24: 17 | B24: Qualicorp | C24: Cintya Camargo | D24: 🔝 Topo | F24: 4066076 | G24: 45994.626 | H24: 15818.113 | I24: 0.34448174 | J24: 2.7030062 | K24: 0.25175178 | L24: 0.07642562 | M24: 0.018900028 | N24: 0.012445446 | O24: 17 | P24: Conta de alto volume — gestão pelo time de key accounts
A25: 18 | B25: Grupo Avenida | C25: Anne Tulio | D25: 🔝 Topo | F25: 4570520 | G25: 43218.853 | H25: 12048.712 | I25: 0.27878353 | J25: -0.63974121 | K25: -0.61949675 | L25: -0.41887258 | M25: 0.017759412 | N25: 0.0094797393 | O25: 18 | P25: Conta de alto volume — gestão pelo time de key accounts
A26: 19 | B26: Grupo Moura | C26: Anne Tulio | D26: 🔝 Topo | F26: 2536091 | G26: 42963.595 | H26: 38698.098 | I26: 0.90053705 | J26: 0.27465566 | K26: 0.12521075 | L26: 0.005130519 | M26: 0.017654522 | N26: 0.030447062 | O26: 19 | P26: Conta de alto volume — gestão pelo time de key accounts
A27: 20 | B27: BRF Brazil | C27: Josue Moro | D27: 🔝 Topo | F27: 7879017 | G27: 41978.886 | H27: 37401.187 | I27: 0.89060994 | J27: -0.094005555 | K27: -0.17956546 | L27: -0.075941552 | M27: 0.017249887 | N27: 0.029426672 | O27: 20 | P27: Conta de alto volume — gestão pelo time de key accounts
A28: 21 | B28: Groupe Renault | C28: Josue Moro | D28: 🔝 Topo | F28: 1480570 | G28: 38235.215 | H28: 17871.868 | I28: 0.46694873 | J28: -0.075797289 | K28: -0.092546923 | L28: -0.16126359 | M28: 0.015711545 | N28: 0.014061307 | O28: 21 | P28: Conta de alto volume — gestão pelo time de key accounts
A29: 22 | B29: Neoenergia Comercializacao | C29: Anne Tulio | D29: 🔝 Topo | F29: 1050428 | G29: 37268.691 | H29: 35938.717 | I29: 0.96423232 | J29: 0.16364636 | K29: 0.046065557 | L29: 0.055663001 | M29: 0.015314382 | N29: 0.028276023 | O29: 22 | P29: Conta de alto volume — gestão pelo time de key accounts
A30: 23 | B30: Assai Atacadista | C30: Josue Moro | D30: 🔝 Topo | F30: 447567 | G30: 37182.636 | H30: 17081.751 | I30: 0.45926713 | J30: 0.19480038 | K30: 0.058853794 | L30: -8.6824836e-05 | M30: 0.015279021 | N30: 0.013439656 | O30: 23 | P30: Conta de alto volume — gestão pelo time de key accounts
A31: 24 | B31: Grupo DPSP | C31: Anne Tulio | D31: 🔝 Topo | F31: 6049828 | G31: 35639.222 | H31: 3364.6518 | I31: 0.09443918 | J31: -0.68260067 | K31: -0.67762363 | L31: -0.60918643 | M31: 0.014644804 | N31: 0.0026472557 | O31: 24 | P31: Conta de alto volume — gestão pelo time de key accounts
... A37: 30 | B37: 123 Milhas | C37: Julia Nunes | D37: 🔝 Topo | F37: 1869540 | G37: 26350.059 | H37: 6732.3185 | I37: 0.25505022 | J37: 0.12951616 | K37: 0.8357189 | L37: 0.3258913 | M37: 0.010827718 | N37: 0.0052968835 | O37: 30 | P37: Conta de alto volume — gestão pelo time de key accounts
A38: 31 | B38: CVC | C38: Willian Julius | D38: 🎯 Mid-Tier | F38: 1593250 | G38: 26288.625 | H38: 1128.521 | I38: 0.042932295 | J38: N/D | K38: N/D | L38: N/D | M38: 0.010802474 | N38: 0.00088790273 | O38: 31 | P38: Conta no bloco de foco — crescimento prioritário 2025
A39: 32 | B39: Wiser | C39: Anne Tulio | D39: 🎯 Mid-Tier | E39: ✅ Sim | F39: 342309 | G39: 26062.069 | H39: 15636.928 | I39: 0.59934232 | J39: -0.58209614 | K39: -0.36514662 | L39: -0.17156966 | M39: 0.010709378 | N39: 0.012302891 | O39: 32 | P39: ⭐ CONTA PRIORITÁRIA — incluída no Mid-Tier Growth Plan 2025
A40: 33 | B40: Azul Linhas Aereas | C40: Julia Nunes | D40: 🎯 Mid-Tier | E40: ✅ Sim | F40: 205345 | G40: 23739.46 | H40: 18718.933 | I40: 0.78868402 | J40: 0.016025292 | K40: 0.026509639 | L40: -0.14203671 | M40: 0.0097549755 | N40: 0.014727765 | O40: 33 | P40: ⭐ CONTA PRIORITÁRIA — incluída no Mid-Tier Growth Plan 2025
A41: 34 | B41: Hospital Oswaldo Cruz | C41: Julia Nunes | D41: 🎯 Mid-Tier | E41: ✅ Sim | F41: 797444 | G41: 20714.051 | H41: 17228.429 | I41: 0.83217181 | J41: -0.068721115 | K41: -0.19277576 | L41: -0.028232587 | M41: 0.0085117801 | N41: 0.01355506 | O41: 34 | P41: ⭐ CONTA PRIORITÁRIA — incluída no Mid-Tier Growth Plan 2025
A42: 35 | B42: McDonalds Brazil | C42: Cintya Camargo | D42: 🎯 Mid-Tier | E42: ✅ Sim | F42: 408594 | G42: 20525.904 | H42: 19046.586 | I42: 0.92723286 | J42: -0.6037929 | K42: -0.79453197 | L42: -0.77410114 | M42: 0.0084344668 | N42: 0.014985558 | O42: 35 | P42: ⭐ CONTA PRIORITÁRIA — incluída no Mid-Tier Growth Plan 2025
A43: 36 | B43: Outback Brazil | C43: Anne Tulio | D43: 🎯 Mid-Tier | E43: ✅ Sim | F43: 1095033 | G43: 15618.684 | H43: 5098.1387 | I43: 0.32574142 | J43: 0.66335984 | K43: 0.3134408 | L43: -0.030294403 | M43: 0.0064180011 | N43: 0.0040111362 | O43: 36 | P43: ⭐ CONTA PRIORITÁRIA — incluída no Mid-Tier Growth Plan 2025
A44: 37 | B44: Pernod Ricard | C44: Anne Tulio | D44: 🎯 Mid-Tier | E44: ✅ Sim | F44: 43172 | G44: 15608.29 | H44: 14092.076 | I44: 0.90192264 | J44: -0.72408726 | K44: -0.0038819331 | L44: 0.17338613 | M44: 0.00641373 | N44: 0.011087426 | O44: 37 | P44: ⭐ CONTA PRIORITÁRIA — incluída no Mid-Tier Growth Plan 2025
A45: 38 | B45: COMM | C45: Anne Tulio | D45: 🎯 Mid-Tier | F45: 1669555 | G45: 14580.621 | H45: 4213.3141 | I45: 0.28897974 | J45: -0.11680969 | K45: -0.062115478 | L45: -0.074922668 | M45: 0.0059914419 | N45: 0.00331497 | O45: 38 | P45: Conta no bloco de foco — crescimento prioritário 2025
A46: 39 | B46: MaxMilhas | C46: Julia Nunes | D46: 🎯 Mid-Tier | E46: ✅ Sim | F46: 3124360 | G46: 14221.734 | H46: 5572.9623 | I46: 0.39218282 | J46: 0.31067227 | K46: 0.30485228 | L46: 0.19531061 | M46: 0.0058439691 | N46: 0.00438472 | O46: 39 | P46: ⭐ CONTA PRIORITÁRIA — incluída no Mid-Tier Growth Plan 2025
...
